# 错误处理（额外知识补充）

## 默认情况下的错误处理

**情况一**：假设此时有一个函数：

```js
function foo() {
  "abc".filter()
}

foo()
const name = "meiciko"
const obj = {}
```

上述代码在第2步出错后，后续代码就全部不会再继续执行了，但是假设后面的某一个操作是一个必须的操作，就无法被执行到。

**情况二**：开发中自己封装了一个函数：

```js
function sum(num1, num2) {
  return num1 + num2
}
// 此时假设有另一个人使用了这个函数
sum([1, 2], [3, 4]) // 出错：加成了字符串
```

所以往往会对传入的参数进行验证：一般采用的做法是如果没有通过某些参数验证，就抛出一个错误：

```js
function sum(num1, num2) {
  if (typeof num1 !== "number" || typeof num2 !== "number") {
    throw new Error("参数类型有误")
  }
  return num1 + num2
}
```



## thorw

- thorw语句用于抛出一个用户自定义的异常；
- ==当遇到throw语句的时候，当前函数执行会被停止==（throw后面的语句不会执行）；



### throw关键跟上的类型

==基础数据类型==：比如number，string，Boolean

==对象类型==：对象类型可以包含更多的信息

==错误信息==：抛出一个 ==Error== 类：首先会告诉被捕获的异常，并且会告诉报错的位置信息。



### Error类

JavaScript提供了一个 ==Error== 类，我们可以直接创建这个类的对象。

这个类有三个属性：

- ==message==：创建Error对象传入的message；
- ==name==：Error的名称，通常和类名称一致；
- ==stack==：整个Error的错误信息，包括函数的调用栈，当我们直接打印Error对象时，打印的就是stack；



### 异常的捕获方式

```js
function fn() {
  console.log("---")
  thorw new Error("未知错误")
  console.log("+++")
}

function test() {
 	fn() 
}

test()
```

在上述代码中，fn出现了一个错误，fn会把这个错误抛给调用者test，但是test也没有处理错误的地方，所以会把错误抛给它的调用者也就是全局，但是全局也没有发现错误处理的地方，就会报错，同时停止执行。

处理错误的语法是 ==try ... catch==

```js
function fn() {
  console.log("---")
  throw new Error("未知错误")
  console.log("+++") // 注意，这一行依然不会执行了
}

function test() {
 	try{
    fn()
  } catch(error) {
    // 错误后的处理方法
  }
}

test()
```

所以，==在我们调用一个函数的时候，这个函数抛出了一场，但是如果并没有对这个异常进行处理，那么这个异常会继续传递到上一个函数调用==中；

==而如果到了最顶层（全局）的代码中依然没有对这个异常的处理代码，这个时候就会报错并且终止程序的运行==。

还可以加入一个 ==finally== 分支，无论有没有报错都会执行

```js
try {
  
} catch(err) {
  
} finally {
  
}
```

